---
id: 019 Python的异常处理
title: 019 Python的异常处理
author: Xxjzp11
author_title: studying
author_url: https://github.com/Xxjzp11
author_image_url: https://avatars2.githubusercontent.com/u/68409850?s=460&u=144d3c818e76fe4b88687db84279fad48b198818&v=4
tags: [python, notes]
---

# 019 Python的异常处理

<!--truncate-->

----------

## Python标准异常总结

| 异常名称              | 解释                                                         |
| --------------------- | ------------------------------------------------------------ |
| **AssertionError**    | **断言语句（assert）失败：当assert关键字后边的条件为假时，程序将抛出该异常，一般用于在代码中置入检查点** |
| **AttributeError**    | **尝试访问未知的对象属性：当试图访问的对象属性不存在时抛出的异常** |
| EOFError              | 这个错误基本上是意味着它发现了一个不期望的文件尾。（UNIX上为Ctrl+d，Windows上为Ctrl+Z+Enter） |
| FloatingPointError    | 浮点计算错误                                                 |
| GeneratorExit         | Gengeator.close()方法被调用的时候                            |
| ImportError           | 导入模块失败的时候                                           |
| **IndexError**        | **索引超出序列的范围**                                       |
| **KeyError**          | **字典中查找一个不存在的关键字**                             |
| KeyboardError         | 用户输入中断键（Ctrl+c）                                     |
| MemoryError           | 内存溢出（可通过删除对象释放内存）                           |
| **NameError**         | **尝试访问一个不存在的变量**                                 |
| NotImplementedError   | 尚未实现的方法                                               |
| **OSError**           | **操作系统产生的异常（例如打开一个不存在的文件）**           |
| OverflowError         | 数值运算超出最大限制                                         |
| ReferenceError        | 弱引用（weak reference）试图访问一个已经被垃圾回收几只回收了的对象 |
| RuntimeError          | 一般的运行时错误                                             |
| StopIteration         | 迭代器没有更多的值                                           |
| **SyntaxError**       | **Python的语法错误**                                         |
| IndentationError      | 缩进错误                                                     |
| TabError              | Tab和空格混合使用                                            |
| SystemError           | Python编译器系统错误                                         |
| SystenExit            | Python编译器进程被关闭                                       |
| **TypeError**         | **不同类型间的无效操作**                                     |
| UnboundLocalError     | 访问一个未初始化的本地变量（NameError的子类）                |
| UnicodeError          | Unicode相关的错误（ValueError的子类）                        |
| UnicodeEncodeError    | Unicode编码时的错误（UnicodeError的子类）                    |
| UnicodeDecodeError    | Unicode解码时的错误（UnicodeError的子类）                    |
| UnicodeTranslateError | Unicode转换时的错误（UnicodeError的子类）                    |
| ValueError            | 传入无效的参数                                               |
| **ZeroDivisionError** | **除数为零**                                                 |

-------------------------

## try-except语句

```python
try:
    检测范围
except Exception[as reason]:
    出现异常（Exception）后的处理代码
```

举个例子：

```python
 try:
    f=open('不存在的文件.txt')
    print(f.read())
    f.close()
except OSError as reason:
    print('文件出错了\n错误原因是：' + str(reason))

输出：

文件出错了
错误原因是：[Errno 2] No such file or directory: '不存在的文件.txt'
```

```python
 try:
    f = open('不存在的文件.txt')
    print(f.read())
    sum = 1 + '1'
    f.close()
except (OSError, TypeError):
    print('出错了')
```

## try-finally语句

```python
try:
    检测范围
except Exception[as reason]:
    出现异常（Exception）后的处理代码
finally:
    无论如何都会被执行的代码
```

```python
 try:
    f = open('不存在的文件.txt', 'w')
    print(f.write('我存在了'))
    sum = 1 + '1'
except (OSError, TypeError):
    print('出错了')
finally:
    f.close()
```

## raise语句：

```java
>>> raise ZeroDivisionError('除数为零的异常')
<span style="color:#ff0000;">Traceback (most recent call last):
  File "<pyshell#0>", line 1, in <module>
    raise ZeroDivisionError('除数为零的异常')
ZeroDivisionError: 除数为零的异常</span>
```

-------------------

## 测试题一

**0.结合你自身的编程经验，总结下异常处理机制的重要性？**

由于环境的不确定性和用户操作的不可以预知性都可能导致程序出现各种问题，因此异常机制最重要的无非就是：**增强程序的健壮性和用户体验，尽可能的捕获所有预知的异常并写好处理的代码，当异常出现的时候，程序自动消化并恢复正常（不至于崩溃）**



**1. 请问以下代码是否会产生异常，如果会的话，请写出异常的名称：**

```python
>>> my_list = [1, 2, 3, 4,,]
```

语法错误

`SyntaxError: invalid syntax.`



**2. 请问以下代码是否会产生异常，如果会的话，请写出异常的名称：**

```python
>>> my_list = [1, 2, 3, 4, 5]
>>> print(my_list[len(my_list)])
```

列表越界

`Indexerror: list index out of range.`



**3. 请问以下代码是否会产生异常，如果会的话，请写出异常的名称：**

```python
>>> my_list = [3, 5, 1, 4, 2]
>>> my_list.sorted()
```

尝试访问未知的对象属性

`AttributeError: 'list' object has no attribute 'sorted'`



**4. 请问以下代码是否会产生异常，如果会的话，请写出异常的名称：**

```python
>>> my_dict = {'host': 'http://bbs.fishc.com', 'port': '80'}`
`>>> print(my_dict['server'])
```

键不存在

`KeyError:`建议使用dict.get()方法预防



**5. 请问以下代码是否会产生异常，如果会的话，请写出异常的名称：**

```python
def my_fun(x, y):
        print(x, y) 
my_fun(x=1, 2)
```

`SyntaxError: positional argument follows keyword argument.`

要么就都是关键字参数my_fun(x=1, y=2)，要么就关键字参数必须跟随在位置参数后面my_fun(1,y=2)



**6. 请问以下代码是否会产生异常，如果会的话，请写出异常的名称：**

```python
f = open('C:\\test.txt', wb)
f.write('I love FishC.com!\n')
f.close()
```

NameError: name 'wb' is not defined.

注意 open() 第二个参数是字符串，应该 f = open('C:\test.txt', 'wb') 。wb不加双引号 Python 还以为是变量名呢，往上一找，艾玛没找着……引发 NameError 异常。由于打开文件失败，接着下边一连串与 f 相关的均会报同样异常



**7. 请问以下代码是否会产生异常，如果会的话，请写出异常的名称：**

```python
def my_fun1():
        x = 5
        def my_fun2():
                x *= x  # 错误在这里
                return x
        return my_fun2()
 
my_fun1()
```

`UnboundLocalError: local variable 'x' referenced before assignment.`

闭包的知识大家还记得不？ Python 认为在内部函数的 x 是局部变量的时候，外部函数的 x 就被屏蔽了起来，所以执行 x *= x 的时候，在右边根本就找不到局部变量 x 的值，因此报错。

在 Python3 之前没有直接的解决方案，只能间接地通过容器类型来存放，因为容器类型不是放在栈里，所以不会

被“屏蔽”掉。容器类型这个词儿大家是不是似曾相识？我们之前介绍的字符串、列表、元祖，这些啥都可以往里的扔的就是容器类型啦。

于是乎我们可以把代码改造为：

```python
def my_fun1():
        x = [5]
        def my_fun2():
                x[0] *= x[0]
                return x[0]
        return my_fun2()
 
my_fun1()
```

但是到了 Python3 的世界里，又有了不少的改进，如果我们希望在内部函数里可以修改外部函数里的局部变量的值，那么也有一个关键字可以使用，就是 nonlocal：

```python
def my_fun1():
        x = 5
        def my_fun2():
                nonlocal x
                x *= x
                return x
        return my_fun2()
 
my_fun1()
```

------------------------

## 测试题二

**0. 我们使用什么方法来处理程序中出现的异常？**

使用 try……except 搭配来捕获处理程序中出现的异常

```python
try:
    检测范围
except Exception[as reason]:
    出现异常（Exception）后的处理代码
```



**1. 一个 try 语句可以和多个 except 语句搭配吗？为什么？**

可以。因为 try 语句块中可能出现多类异常，利用多个 except 语句可以分别捕获并处理我们感兴趣的异常

```python
try:
    sum = 1 + '1'
    f = open('我是一个不存在的文档.txt')
    print(f.read())
    f.close()
except OSError as reason:
    print('文件出错啦T_T\n错误原因是：' + str(reason))
except TypeError as reason:
    print('类型出错啦T_T\n错误原因是：' + str(reason))

输出：

类型出错啦T_T
错误原因是：unsupported operand type(s) for +: 'int' and 'str'
```



**2. 你知道如何统一处理多类异常吗？**

在 except 后边使用小括号“()”把多个需要统一处理的异常括起来

```dart
try:
    int('abc')
    sum = 1 + '1'
    f = open('我是一个不存在的文档.txt')
    print(f.read())
    f.close()
except (OSError, TypeError, ValueError) as reason:
    print('出错啦T_T\n错误原因是：' + str(reason))

输出：

出错啦T_T
错误原因是：invalid literal for int() with base 10: 'abc'
```



**3. except 后边如果不带任何异常类，Python 会捕获所有（try 语句块内）的异常并统一处理，但小甲鱼却不建议这么做，你知道为什么吗？**

因为它会隐藏所有程序员未想到并且未做好准备处理的错误，例如用户输入ctrl+c试图终止程序会被解释为KeyboardInterrupt异常



**4. 如果异常发生在成功打开文件后，Python 跳到 except 语句执行，并没有执行关闭文件的命令（用户写入文件的数据就可能没有保存起来），因此我们需要确保无论如何（就算出了异常退出）文件也要被关闭，我们应该怎么做呢？**

我们可以使用 finally 语句来实现，如果 try 语句块中没有出现任何运行时错误，会跳过 except 语句块执行 finally语句块的内容。如果出现异常，则会先执行 except 语句块的内容再接着执行 finally 语句块的内容。总之，finally 语句块里的内容就是确保无论如何都将被执行的内容！

```python
#举个例子：
 try:
    f = open('a.txt')
    print(f.read())
    sum = 1 + '1'
except:
    print('出错了')
finally:
    f.close()

输出：

...这里是输出的是a.txt文件内容...
出错了
```



**5. 请恢复以下代码中马赛克挡住的内容，使得程序执行后可以按要求输出。**

![Wew4rd.png](https://z3.ax1x.com/2021/07/14/Wew4rd.png)

```python
try:
    for i in range(3):
        for j in range(3):
            if i == 2:
                raise KeyboardInterrupt
            print(i, j)
except KeyboardInterrupt:
    print('退出啦！')
```



**6. 还记得我们第一个小游戏吗？只要用户输入非整型数据，程序立刻就会蹦出不和谐的异常信息然后崩溃。请使用刚学的异常处理方法修改以下程序，提高用户体验。)**

```python
import random
 
secret = random.randint(1,10)
print('------------------我爱鱼C工作室------------------')
temp = input("不妨猜一下小甲鱼现在心里想的是哪个数字：")
try:    
    guess = int(temp)
except ValueError:
    print('输入错误！')
    guess = secret
while guess != secret:
    temp = input("哎呀，猜错了，请重新输入吧：")
    guess = int(temp)
    if guess == secret:
        print("我草，你是小甲鱼心里的蛔虫吗？！")
        print("哼，猜中了也没有奖励！")
    else:
        if guess > secret:
            print("哥，大了大了~~~")
        else:
            print("嘿，小了，小了~~~")
print("游戏结束，不玩啦^_^")
```



**7. input() 函数有可能产生两类异常：EOFError（文件末尾endoffile，当用户按下组合键 Ctrl+d 产生）和 KeyboardInterrupt（取消输入，当用户按下组合键 Ctrl+c 产生），再次修改上边代码，捕获处理 input() 的两类异常，提高用户体验。**

```python
import random
 
secret = random.randint(1,10)
print('------------------我爱鱼C工作室------------------')
try:
    temp = input("不妨猜一下小甲鱼现在心里想的是哪个数字：")    
    guess = int(temp)
except (ValueError, EOFError, KeyboardInterrupt):
    print('输入错误！')
    guess = secret
while guess != secret:
    temp = input("哎呀，猜错了，请重新输入吧：")
    guess = int(temp)
    if guess == secret:
        print("我草，你是小甲鱼心里的蛔虫吗？！")
        print("哼，猜中了也没有奖励！")
    else:
        if guess > secret:
            print("哥，大了大了~~~")
        else:
            print("嘿，小了，小了~~~")
print("游戏结束，不玩啦^_^")
```



**8. 尝试一个新的函数 int_input()，当用户输入整数的时候正常返回，否则提示出错并要求重新输入。**

![Wew7IP.png](https://z3.ax1x.com/2021/07/14/Wew7IP.png)

```python
def int_input(prompt=''):
    while True:
        try:
            int(input(prompt))
            break
        except ValueError:
            print('出错，您输入的不是整数！')
 
int_input('请输入一个整数：')
```



**9. 把文件关闭放在 finally 语句块中执行还是会出现问题，像下边这个代码，当前文件夹中并不存在"My_File.txt"这个文件，那么程序执行起来会发生什么事情呢？你有办法解决这个问题吗？**

```python
try:
    f = open('My_File.txt') # 当前文件夹中并不存在"My_File.txt"这个文件T_T
    print(f.read())
except OSError as reason:
    print('出错啦：' + str(reason))
finally:
	f.close()
```

由于finally语句块里试图去关闭一个并没有成功打开的文件，因此会弹出错误内容如下：

```python
>>> 出错啦：[Errno 2] No such file or directory: 'My_File.txt'
Traceback (most recent call last):
  File "C:\Users\FishC000\Desktop\test.py", line 7, in <module>
    f.close()
NameError: name 'f' is not defined
```

我们这么修正：

```python
try:
    f = open('My_File.txt') # 当前文件夹中并不存在"My_File.txt"这个文件T_T
    print(f.read())
except OSError as reason:
    print('出错啦：' + str(reason))
finally:
    if 'f' in locals(): # 如果文件对象变量存在当前局部变量符号表的话，说明打开成功
        f.close()
```